Workbook
Name Slicer_Years__created_date1: #N/A

Sheet Subscription Cohort Data
A1: customer_id | B1: created_date | C1: canceled_date | D1: was_subscription_paid | E1: subscription_cost | F1: subscription_interval | G1: Cancellation Duration | H1: weekday
A2: 154536156 | B2: 44805 | C2: Active | D2: Yes | E2: 39 | F2: month | G2: =IF(C2="Active","Active",C2-B2) -> Active | H2: =TEXT(B2,"dddd") -> Thursday | J2: 44879 | K2: =COUNTIF($B$2:$B$3070,J2) -> 20
A3: 149713408 | B3: 44805 | C3: 44806 | D3: No | E3: 39 | F3: month | G3: =IF(C3="Active","Active",C3-B3) -> 1 | H3: =TEXT(B3,"dddd") -> Thursday | J3: 45054 | K3: =COUNTIF($B$2:$B$3070,J3) -> 20
A4: 153756284 | B4: 44805 | C4: 44806 | D4: No | E4: 39 | F4: month | G4: =IF(C4="Active","Active",C4-B4) -> 1 | H4: =TEXT(B4,"dddd") -> Thursday | J4: 44958 | K4: =COUNTIF($B$2:$B$3070,J4) -> 19
A5: 121253113 | B5: 44805 | C5: 44827 | D5: Yes | E5: 39 | F5: month | G5: =IF(C5="Active","Active",C5-B5) -> 22 | H5: =TEXT(B5,"dddd") -> Thursday | J5: 44963 | K5: =COUNTIF($B$2:$B$3070,J5) -> 19
A6: 154467210 | B6: 44805 | C6: 45106 | D6: Yes | E6: 39 | F6: month | G6: =IF(C6="Active","Active",C6-B6) -> 301 | H6: =TEXT(B6,"dddd") -> Thursday | J6: 44809 | K6: =COUNTIF($B$2:$B$3070,J6) -> 18
A7: 154510811 | B7: 44805 | C7: 45054 | D7: Yes | E7: 39 | F7: month | G7: =IF(C7="Active","Active",C7-B7) -> 249 | H7: =TEXT(B7,"dddd") -> Thursday | J7: 45132 | K7: =COUNTIF($B$2:$B$3070,J7) -> 18
A8: 154494346 | B8: 44805 | C8: 44891 | D8: Yes | E8: 39 | F8: month | G8: =IF(C8="Active","Active",C8-B8) -> 86 | H8: =TEXT(B8,"dddd") -> Thursday | J8: 44896 | K8: =COUNTIF($B$2:$B$3070,J8) -> 17
A9: 148671505 | B9: 44805 | C9: 44888 | D9: Yes | E9: 39 | F9: month | G9: =IF(C9="Active","Active",C9-B9) -> 83 | H9: =TEXT(B9,"dddd") -> Thursday | J9: 44872 | K9: =COUNTIF($B$2:$B$3070,J9) -> 16
A10: 154568379 | B10: 44805 | C10: 44859 | D10: Yes | E10: 39 | F10: month | G10: =IF(C10="Active","Active",C10-B10) -> 54 | H10: =TEXT(B10,"dddd") -> Thursday | J10: 44944 | K10: =COUNTIF($B$2:$B$3070,J10) -> 16
A11: 154428434 | B11: 44805 | C11: 44865 | D11: Yes | E11: 39 | F11: month | G11: =IF(C11="Active","Active",C11-B11) -> 60 | H11: =TEXT(B11,"dddd") -> Thursday | J11: 44952 | K11: =COUNTIF($B$2:$B$3070,J11) -> 16
A12: 154601651 | B12: 44805 | C12: 44830 | D12: Yes | E12: 39 | F12: month | G12: =IF(C12="Active","Active",C12-B12) -> 25 | H12: =TEXT(B12,"dddd") -> Thursday | J12: 44966 | K12: =COUNTIF($B$2:$B$3070,J12) -> 16
A13: 122824692 | B13: 44805 | C13: 44819 | D13: Yes | E13: 39 | F13: month | G13: =IF(C13="Active","Active",C13-B13) -> 14 | H13: =TEXT(B13,"dddd") -> Thursday | J13: 45076 | K13: =COUNTIF($B$2:$B$3070,J13) -> 16
A14: 152925600 | B14: 44806 | C14: Active | D14: Yes | E14: 39 | F14: month | G14: =IF(C14="Active","Active",C14-B14) -> Active | H14: =TEXT(B14,"dddd") -> Friday | J14: 45077 | K14: =COUNTIF($B$2:$B$3070,J14) -> 16
A15: 151154171 | B15: 44806 | C15: 44806 | D15: Yes | E15: 39 | F15: month | G15: =IF(C15="Active","Active",C15-B15) -> 0 | H15: =TEXT(B15,"dddd") -> Friday | J15: 45098 | K15: =COUNTIF($B$2:$B$3070,J15) -> 16
A16: 154640950 | B16: 44806 | C16: 44904 | D16: Yes | E16: 39 | F16: month | G16: =IF(C16="Active","Active",C16-B16) -> 98 | H16: =TEXT(B16,"dddd") -> Friday | J16: 45103 | K16: =COUNTIF($B$2:$B$3070,J16) -> 16
A17: 154617329 | B17: 44806 | C17: 44861 | D17: Yes | E17: 39 | F17: month | G17: =IF(C17="Active","Active",C17-B17) -> 55 | H17: =TEXT(B17,"dddd") -> Friday | J17: 45117 | K17: =COUNTIF($B$2:$B$3070,J17) -> 16
A18: 154089211 | B18: 44806 | C18: 44843 | D18: Yes | E18: 39 | F18: month | G18: =IF(C18="Active","Active",C18-B18) -> 37 | H18: =TEXT(B18,"dddd") -> Friday | J18: 45118 | K18: =COUNTIF($B$2:$B$3070,J18) -> 16
A19: 154653820 | B19: 44806 | C19: 44830 | D19: Yes | E19: 39 | F19: month | G19: =IF(C19="Active","Active",C19-B19) -> 24 | H19: =TEXT(B19,"dddd") -> Friday | J19: 45141 | K19: =COUNTIF($B$2:$B$3070,J19) -> 16
A20: 154131290 | B20: 44807 | C20: Active | D20: Yes | E20: 39 | F20: month | G20: =IF(C20="Active","Active",C20-B20) -> Active | H20: =TEXT(B20,"dddd") -> Saturday | J20: 44938 | K20: =COUNTIF($B$2:$B$3070,J20) -> 15
A21: 154434009 | B21: 44807 | C21: Active | D21: Yes | E21: 39 | F21: month | G21: =IF(C21="Active","Active",C21-B21) -> Active | H21: =TEXT(B21,"dddd") -> Saturday | J21: 44953 | K21: =COUNTIF($B$2:$B$3070,J21) -> 15
A22: 136108848 | B22: 44807 | C22: 44808 | D22: Yes | E22: 39 | F22: month | G22: =IF(C22="Active","Active",C22-B22) -> 1 | H22: =TEXT(B22,"dddd") -> Saturday | J22: 44977 | K22: =COUNTIF($B$2:$B$3070,J22) -> 15
A23: 135185873 | B23: 44807 | C23: 45056 | D23: Yes | E23: 39 | F23: month | G23: =IF(C23="Active","Active",C23-B23) -> 249 | H23: =TEXT(B23,"dddd") -> Saturday | J23: 45072 | K23: =COUNTIF($B$2:$B$3070,J23) -> 15
A24: 154592664 | B24: 44807 | C24: 45017 | D24: Yes | E24: 39 | F24: month | G24: =IF(C24="Active","Active",C24-B24) -> 210 | H24: =TEXT(B24,"dddd") -> Saturday | J24: 45097 | K24: =COUNTIF($B$2:$B$3070,J24) -> 15
A25: 119436804 | B25: 44807 | C25: 45026 | D25: Yes | E25: 39 | F25: month | G25: =IF(C25="Active","Active",C25-B25) -> 219 | H25: =TEXT(B25,"dddd") -> Saturday | J25: 45099 | K25: =COUNTIF($B$2:$B$3070,J25) -> 15
A26: 152929657 | B26: 44807 | C26: 44888 | D26: Yes | E26: 39 | F26: month | G26: =IF(C26="Active","Active",C26-B26) -> 81 | H26: =TEXT(B26,"dddd") -> Saturday | J26: 45140 | K26: =COUNTIF($B$2:$B$3070,J26) -> 15
A27: 154708974 | B27: 44807 | C27: 44852 | D27: Yes | E27: 39 | F27: month | G27: =IF(C27="Active","Active",C27-B27) -> 45 | H27: =TEXT(B27,"dddd") -> Saturday | J27: 45173 | K27: =COUNTIF($B$2:$B$3070,J27) -> 15
A28: 154567722 | B28: 44807 | C28: 44833 | D28: Yes | E28: 39 | F28: month | G28: =IF(C28="Active","Active",C28-B28) -> 26 | H28: =TEXT(B28,"dddd") -> Saturday | J28: 44959 | K28: =COUNTIF($B$2:$B$3070,J28) -> 14
A29: 154719788 | B29: 44807 | C29: 44829 | D29: Yes | E29: 39 | F29: month | G29: =IF(C29="Active","Active",C29-B29) -> 22 | H29: =TEXT(B29,"dddd") -> Saturday | J29: 44987 | K29: =COUNTIF($B$2:$B$3070,J29) -> 14
A30: 154809306 | B30: 44808 | C30: 44809 | D30: Yes | E30: 39 | F30: month | G30: =IF(C30="Active","Active",C30-B30) -> 1 | H30: =TEXT(B30,"dddd") -> Sunday | J30: 45040 | K30: =COUNTIF($B$2:$B$3070,J30) -> 14
A31: 140391539 | B31: 44808 | C31: 45021 | D31: Yes | E31: 39 | F31: month | G31: =IF(C31="Active","Active",C31-B31) -> 213 | H31: =TEXT(B31,"dddd") -> Sunday | J31: 45055 | K31: =COUNTIF($B$2:$B$3070,J31) -> 14
A32: 153194806 | B32: 44808 | C32: 45032 | D32: Yes | E32: 39 | F32: month | G32: =IF(C32="Active","Active",C32-B32) -> 224 | H32: =TEXT(B32,"dddd") -> Sunday | J32: 45107 | K32: =COUNTIF($B$2:$B$3070,J32) -> 14
A33: 144402204 | B33: 44808 | C33: 44826 | D33: Yes | E33: 39 | F33: month | G33: =IF(C33="Active","Active",C33-B33) -> 18 | H33: =TEXT(B33,"dddd") -> Sunday | J33: 45124 | K33: =COUNTIF($B$2:$B$3070,J33) -> 14
... A38: 153368891 | B38: 44808 | C38: 44845 | D38: Yes | E38: 39 | F38: month | G38: =IF(C38="Active","Active",C38-B38) -> 37 | H38: =TEXT(B38,"dddd") -> Sunday | J38: 44819 | K38: =COUNTIF($B$2:$B$3070,J38) -> 13
A39: 154225450 | B39: 44809 | C39: Active | D39: Yes | E39: 39 | F39: month | G39: =IF(C39="Active","Active",C39-B39) -> Active | H39: =TEXT(B39,"dddd") -> Monday | J39: 44837 | K39: =COUNTIF($B$2:$B$3070,J39) -> 13
A40: 154904040 | B40: 44809 | C40: 44810 | D40: Yes | E40: 39 | F40: month | G40: =IF(C40="Active","Active",C40-B40) -> 1 | H40: =TEXT(B40,"dddd") -> Monday | J40: 44897 | K40: =COUNTIF($B$2:$B$3070,J40) -> 13
A41: 127604200 | B41: 44809 | C41: 44840 | D41: Yes | E41: 39 | F41: month | G41: =IF(C41="Active","Active",C41-B41) -> 31 | H41: =TEXT(B41,"dddd") -> Monday | J41: 44951 | K41: =COUNTIF($B$2:$B$3070,J41) -> 13
A42: 154913576 | B42: 44809 | C42: 44998 | D42: Yes | E42: 39 | F42: month | G42: =IF(C42="Active","Active",C42-B42) -> 189 | H42: =TEXT(B42,"dddd") -> Monday | J42: 44965 | K42: =COUNTIF($B$2:$B$3070,J42) -> 13
A43: 154910432 | B43: 44809 | C43: 44998 | D43: Yes | E43: 39 | F43: month | G43: =IF(C43="Active","Active",C43-B43) -> 189 | H43: =TEXT(B43,"dddd") -> Monday | J43: 44976 | K43: =COUNTIF($B$2:$B$3070,J43) -> 13
A44: 154911229 | B44: 44809 | C44: 44997 | D44: Yes | E44: 39 | F44: month | G44: =IF(C44="Active","Active",C44-B44) -> 188 | H44: =TEXT(B44,"dddd") -> Monday | J44: 44979 | K44: =COUNTIF($B$2:$B$3070,J44) -> 13
...

Sheet Data Description
B2: Field | C2: Description
B3: customer_id | C3: Unique customer identification number representing an individual customer
B4: created_date | C4: Date the customer subscription was created (DD/MM/YYYY).
B5: canceled_date | C5: Date the customer subscription was canceled (DD/MM/YYYY). If value is blank then the subscription has not been canceled
B6: subscription_cost | C6: Price of the subscription in USD
B7: subscription_interval | C7: Measurement of time between billing occurrences for a recurring billing subscription
B8: was_subscription_paid | C8: Indicates if payment was successfully collected for a subscription

Sheet Questions for Analysis 
A1: Questions for Analysis:
A5: 1. Which date had the highest number of subscriptions cancellations?
B7: Cancelled Date | C7: Count of canceled_date
B8: 45104 | C8: 14
A10: 2. How many subscriptions were canceled on the same day they were created?
D12: =COUNTIF('Data prepration'!$I$2:$I$3070,"Yes") -> 108
A14: 3. What is the cancellation rate within the first two days of subscription?
C16: cancel | D16: =COUNTIF('Data prepration'!$J$2:$J$3070,1) -> 293
C17: total cancel | D17: =COUNT('Data prepration'!$J$2:$J$3070) -> 3069
C18: cancellation_rate | D18: =(D16/D17) -> 0.095470837
A20: 4. How many subscriptions lasted more than one month?
D21: =COUNTIFS(Table1[sub_more_than_1_month],1) -> 1267
A23: 5. What is the most common duration before cancellation?
D24: =_xlfn.MODE.SNGL('Data prepration'!L2:L3070) -> 1
A26: 6. How does the number of subscriptions vary by day?
C28: Weekday | D28: Count of customer_id
C29: Monday | D29: 539
C30: Thursday | D30: 505
C31: Tuesday | D31: 487
C32: Wednesday | D32: 472
C33: Friday | D33: 452
C34: Saturday | D34: 308
C35: Sunday | D35: 306
A38: 7. Are there any indications that unpaid subscriptions have a higher cancellation rate?
C40: Subscription Paid | D40: Count of created_date | E40: Count of canceled_date | F40: Cancellation rate
C41: No | D41: 133 | E41: 123 | F41: =GETPIVOTDATA("Count of canceled_date",$C$40,"was_subscription_paid","No")/GETPIVOTDATA("Count of created_date",$C$40,"was_subscription_paid","No") -> 0.92481203
C42: Yes | D42: 2936 | E42: 1881 | F42: =GETPIVOTDATA("Count of canceled_date",$C$40,"was_subscription_paid","Yes")/GETPIVOTDATA("Count of created_date",$C$40,"was_subscription_paid","Yes") -> 0.64066757
D43: =GETPIVOTDATA("Count of created_date",$C$40,"was_subscription_paid","No")+GETPIVOTDATA("Count of created_date",$C$40,"was_subscription_paid","Yes") -> 3069 | E43: =GETPIVOTDATA("Count of canceled_date",$C$40,"was_subscription_paid","No")+GETPIVOTDATA("Count of canceled_date",$C$40,"was_subscription_paid","Yes") -> 2004

Sheet Data prepration
A1: customer_id | B1: created_date | C1: canceled_date | D1: was_subscription_paid | E1: subscription_cost | F1: subscription_interval | G1: Cancellation Duration | H1: weekday | I1: same_day_cancel | J1: cancel_within_2days | K1: sub_more_than_1_month | L1: count_days_before_cancel
A2: 154536156 | B2: 44805 | D2: Yes | E2: 39 | F2: month | G2: =IF(C2="","",C2-B2) | H2: =TEXT(B2,"dddd") -> Thursday | I2: =IF(B2=C2,"Yes","No") -> No | J2: =IF(AND(C2<>"",C2-B2<=2),1,0) -> 0 | K2: =IF(AND(C2<>"",C2-B2>30),1,0) -> 0 | L2: =IF(C2="","",C2-B2)
A3: 149713408 | B3: 44805 | C3: 44806 | D3: No | E3: 39 | F3: month | G3: =IF(C3="","",C3-B3) -> 1 | H3: =TEXT(B3,"dddd") -> Thursday | I3: =IF(B3=C3,"Yes","No") -> No | J3: =IF(AND(C3<>"",C3-B3<=2),1,0) -> 1 | K3: =IF(AND(C3<>"",C3-B3>30),1,0) -> 0 | L3: =IF(C3="","",C3-B3) -> 1
A4: 153756284 | B4: 44805 | C4: 44806 | D4: No | E4: 39 | F4: month | G4: =IF(C4="","",C4-B4) -> 1 | H4: =TEXT(B4,"dddd") -> Thursday | I4: =IF(B4=C4,"Yes","No") -> No | J4: =IF(AND(C4<>"",C4-B4<=2),1,0) -> 1 | K4: =IF(AND(C4<>"",C4-B4>30),1,0) -> 0 | L4: =IF(C4="","",C4-B4) -> 1
A5: 121253113 | B5: 44805 | C5: 44827 | D5: Yes | E5: 39 | F5: month | G5: =IF(C5="","",C5-B5) -> 22 | H5: =TEXT(B5,"dddd") -> Thursday | I5: =IF(B5=C5,"Yes","No") -> No | J5: =IF(AND(C5<>"",C5-B5<=2),1,0) -> 0 | K5: =IF(AND(C5<>"",C5-B5>30),1,0) -> 0 | L5: =IF(C5="","",C5-B5) -> 22
A6: 154467210 | B6: 44805 | C6: 45106 | D6: Yes | E6: 39 | F6: month | G6: =IF(C6="","",C6-B6) -> 301 | H6: =TEXT(B6,"dddd") -> Thursday | I6: =IF(B6=C6,"Yes","No") -> No | J6: =IF(AND(C6<>"",C6-B6<=2),1,0) -> 0 | K6: =IF(AND(C6<>"",C6-B6>30),1,0) -> 1 | L6: =IF(C6="","",C6-B6) -> 301
A7: 154510811 | B7: 44805 | C7: 45054 | D7: Yes | E7: 39 | F7: month | G7: =IF(C7="","",C7-B7) -> 249 | H7: =TEXT(B7,"dddd") -> Thursday | I7: =IF(B7=C7,"Yes","No") -> No | J7: =IF(AND(C7<>"",C7-B7<=2),1,0) -> 0 | K7: =IF(AND(C7<>"",C7-B7>30),1,0) -> 1 | L7: =IF(C7="","",C7-B7) -> 249
A8: 154494346 | B8: 44805 | C8: 44891 | D8: Yes | E8: 39 | F8: month | G8: =IF(C8="","",C8-B8) -> 86 | H8: =TEXT(B8,"dddd") -> Thursday | I8: =IF(B8=C8,"Yes","No") -> No | J8: =IF(AND(C8<>"",C8-B8<=2),1,0) -> 0 | K8: =IF(AND(C8<>"",C8-B8>30),1,0) -> 1 | L8: =IF(C8="","",C8-B8) -> 86
A9: 148671505 | B9: 44805 | C9: 44888 | D9: Yes | E9: 39 | F9: month | G9: =IF(C9="","",C9-B9) -> 83 | H9: =TEXT(B9,"dddd") -> Thursday | I9: =IF(B9=C9,"Yes","No") -> No | J9: =IF(AND(C9<>"",C9-B9<=2),1,0) -> 0 | K9: =IF(AND(C9<>"",C9-B9>30),1,0) -> 1 | L9: =IF(C9="","",C9-B9) -> 83
A10: 154568379 | B10: 44805 | C10: 44859 | D10: Yes | E10: 39 | F10: month | G10: =IF(C10="","",C10-B10) -> 54 | H10: =TEXT(B10,"dddd") -> Thursday | I10: =IF(B10=C10,"Yes","No") -> No | J10: =IF(AND(C10<>"",C10-B10<=2),1,0) -> 0 | K10: =IF(AND(C10<>"",C10-B10>30),1,0) -> 1 | L10: =IF(C10="","",C10-B10) -> 54
A11: 154428434 | B11: 44805 | C11: 44865 | D11: Yes | E11: 39 | F11: month | G11: =IF(C11="","",C11-B11) -> 60 | H11: =TEXT(B11,"dddd") -> Thursday | I11: =IF(B11=C11,"Yes","No") -> No | J11: =IF(AND(C11<>"",C11-B11<=2),1,0) -> 0 | K11: =IF(AND(C11<>"",C11-B11>30),1,0) -> 1 | L11: =IF(C11="","",C11-B11) -> 60
A12: 154601651 | B12: 44805 | C12: 44830 | D12: Yes | E12: 39 | F12: month | G12: =IF(C12="","",C12-B12) -> 25 | H12: =TEXT(B12,"dddd") -> Thursday | I12: =IF(B12=C12,"Yes","No") -> No | J12: =IF(AND(C12<>"",C12-B12<=2),1,0) -> 0 | K12: =IF(AND(C12<>"",C12-B12>30),1,0) -> 0 | L12: =IF(C12="","",C12-B12) -> 25
A13: 122824692 | B13: 44805 | C13: 44819 | D13: Yes | E13: 39 | F13: month | G13: =IF(C13="","",C13-B13) -> 14 | H13: =TEXT(B13,"dddd") -> Thursday | I13: =IF(B13=C13,"Yes","No") -> No | J13: =IF(AND(C13<>"",C13-B13<=2),1,0) -> 0 | K13: =IF(AND(C13<>"",C13-B13>30),1,0) -> 0 | L13: =IF(C13="","",C13-B13) -> 14
A14: 152925600 | B14: 44806 | D14: Yes | E14: 39 | F14: month | G14: =IF(C14="","",C14-B14) | H14: =TEXT(B14,"dddd") -> Friday | I14: =IF(B14=C14,"Yes","No") -> No | J14: =IF(AND(C14<>"",C14-B14<=2),1,0) -> 0 | K14: =IF(AND(C14<>"",C14-B14>30),1,0) -> 0 | L14: =IF(C14="","",C14-B14)
A15: 151154171 | B15: 44806 | C15: 44806 | D15: Yes | E15: 39 | F15: month | G15: =IF(C15="","",C15-B15) -> 0 | H15: =TEXT(B15,"dddd") -> Friday | I15: =IF(B15=C15,"Yes","No") -> Yes | J15: =IF(AND(C15<>"",C15-B15<=2),1,0) -> 1 | K15: =IF(AND(C15<>"",C15-B15>30),1,0) -> 0 | L15: =IF(C15="","",C15-B15) -> 0
A16: 154640950 | B16: 44806 | C16: 44904 | D16: Yes | E16: 39 | F16: month | G16: =IF(C16="","",C16-B16) -> 98 | H16: =TEXT(B16,"dddd") -> Friday | I16: =IF(B16=C16,"Yes","No") -> No | J16: =IF(AND(C16<>"",C16-B16<=2),1,0) -> 0 | K16: =IF(AND(C16<>"",C16-B16>30),1,0) -> 1 | L16: =IF(C16="","",C16-B16) -> 98
A17: 154617329 | B17: 44806 | C17: 44861 | D17: Yes | E17: 39 | F17: month | G17: =IF(C17="","",C17-B17) -> 55 | H17: =TEXT(B17,"dddd") -> Friday | I17: =IF(B17=C17,"Yes","No") -> No | J17: =IF(AND(C17<>"",C17-B17<=2),1,0) -> 0 | K17: =IF(AND(C17<>"",C17-B17>30),1,0) -> 1 | L17: =IF(C17="","",C17-B17) -> 55
A18: 154089211 | B18: 44806 | C18: 44843 | D18: Yes | E18: 39 | F18: month | G18: =IF(C18="","",C18-B18) -> 37 | H18: =TEXT(B18,"dddd") -> Friday | I18: =IF(B18=C18,"Yes","No") -> No | J18: =IF(AND(C18<>"",C18-B18<=2),1,0) -> 0 | K18: =IF(AND(C18<>"",C18-B18>30),1,0) -> 1 | L18: =IF(C18="","",C18-B18) -> 37
A19: 154653820 | B19: 44806 | C19: 44830 | D19: Yes | E19: 39 | F19: month | G19: =IF(C19="","",C19-B19) -> 24 | H19: =TEXT(B19,"dddd") -> Friday | I19: =IF(B19=C19,"Yes","No") -> No | J19: =IF(AND(C19<>"",C19-B19<=2),1,0) -> 0 | K19: =IF(AND(C19<>"",C19-B19>30),1,0) -> 0 | L19: =IF(C19="","",C19-B19) -> 24
A20: 154131290 | B20: 44807 | D20: Yes | E20: 39 | F20: month | G20: =IF(C20="","",C20-B20) | H20: =TEXT(B20,"dddd") -> Saturday | I20: =IF(B20=C20,"Yes","No") -> No | J20: =IF(AND(C20<>"",C20-B20<=2),1,0) -> 0 | K20: =IF(AND(C20<>"",C20-B20>30),1,0) -> 0 | L20: =IF(C20="","",C20-B20)
A21: 154434009 | B21: 44807 | D21: Yes | E21: 39 | F21: month | G21: =IF(C21="","",C21-B21) | H21: =TEXT(B21,"dddd") -> Saturday | I21: =IF(B21=C21,"Yes","No") -> No | J21: =IF(AND(C21<>"",C21-B21<=2),1,0) -> 0 | K21: =IF(AND(C21<>"",C21-B21>30),1,0) -> 0 | L21: =IF(C21="","",C21-B21)
A22: 136108848 | B22: 44807 | C22: 44808 | D22: Yes | E22: 39 | F22: month | G22: =IF(C22="","",C22-B22) -> 1 | H22: =TEXT(B22,"dddd") -> Saturday | I22: =IF(B22=C22,"Yes","No") -> No | J22: =IF(AND(C22<>"",C22-B22<=2),1,0) -> 1 | K22: =IF(AND(C22<>"",C22-B22>30),1,0) -> 0 | L22: =IF(C22="","",C22-B22) -> 1
A23: 135185873 | B23: 44807 | C23: 45056 | D23: Yes | E23: 39 | F23: month | G23: =IF(C23="","",C23-B23) -> 249 | H23: =TEXT(B23,"dddd") -> Saturday | I23: =IF(B23=C23,"Yes","No") -> No | J23: =IF(AND(C23<>"",C23-B23<=2),1,0) -> 0 | K23: =IF(AND(C23<>"",C23-B23>30),1,0) -> 1 | L23: =IF(C23="","",C23-B23) -> 249
A24: 154592664 | B24: 44807 | C24: 45017 | D24: Yes | E24: 39 | F24: month | G24: =IF(C24="","",C24-B24) -> 210 | H24: =TEXT(B24,"dddd") -> Saturday | I24: =IF(B24=C24,"Yes","No") -> No | J24: =IF(AND(C24<>"",C24-B24<=2),1,0) -> 0 | K24: =IF(AND(C24<>"",C24-B24>30),1,0) -> 1 | L24: =IF(C24="","",C24-B24) -> 210
A25: 119436804 | B25: 44807 | C25: 45026 | D25: Yes | E25: 39 | F25: month | G25: =IF(C25="","",C25-B25) -> 219 | H25: =TEXT(B25,"dddd") -> Saturday | I25: =IF(B25=C25,"Yes","No") -> No | J25: =IF(AND(C25<>"",C25-B25<=2),1,0) -> 0 | K25: =IF(AND(C25<>"",C25-B25>30),1,0) -> 1 | L25: =IF(C25="","",C25-B25) -> 219
A26: 152929657 | B26: 44807 | C26: 44888 | D26: Yes | E26: 39 | F26: month | G26: =IF(C26="","",C26-B26) -> 81 | H26: =TEXT(B26,"dddd") -> Saturday | I26: =IF(B26=C26,"Yes","No") -> No | J26: =IF(AND(C26<>"",C26-B26<=2),1,0) -> 0 | K26: =IF(AND(C26<>"",C26-B26>30),1,0) -> 1 | L26: =IF(C26="","",C26-B26) -> 81
A27: 154708974 | B27: 44807 | C27: 44852 | D27: Yes | E27: 39 | F27: month | G27: =IF(C27="","",C27-B27) -> 45 | H27: =TEXT(B27,"dddd") -> Saturday | I27: =IF(B27=C27,"Yes","No") -> No | J27: =IF(AND(C27<>"",C27-B27<=2),1,0) -> 0 | K27: =IF(AND(C27<>"",C27-B27>30),1,0) -> 1 | L27: =IF(C27="","",C27-B27) -> 45
A28: 154567722 | B28: 44807 | C28: 44833 | D28: Yes | E28: 39 | F28: month | G28: =IF(C28="","",C28-B28) -> 26 | H28: =TEXT(B28,"dddd") -> Saturday | I28: =IF(B28=C28,"Yes","No") -> No | J28: =IF(AND(C28<>"",C28-B28<=2),1,0) -> 0 | K28: =IF(AND(C28<>"",C28-B28>30),1,0) -> 0 | L28: =IF(C28="","",C28-B28) -> 26
A29: 154719788 | B29: 44807 | C29: 44829 | D29: Yes | E29: 39 | F29: month | G29: =IF(C29="","",C29-B29) -> 22 | H29: =TEXT(B29,"dddd") -> Saturday | I29: =IF(B29=C29,"Yes","No") -> No | J29: =IF(AND(C29<>"",C29-B29<=2),1,0) -> 0 | K29: =IF(AND(C29<>"",C29-B29>30),1,0) -> 0 | L29: =IF(C29="","",C29-B29) -> 22
A30: 154809306 | B30: 44808 | C30: 44809 | D30: Yes | E30: 39 | F30: month | G30: =IF(C30="","",C30-B30) -> 1 | H30: =TEXT(B30,"dddd") -> Sunday | I30: =IF(B30=C30,"Yes","No") -> No | J30: =IF(AND(C30<>"",C30-B30<=2),1,0) -> 1 | K30: =IF(AND(C30<>"",C30-B30>30),1,0) -> 0 | L30: =IF(C30="","",C30-B30) -> 1
A31: 140391539 | B31: 44808 | C31: 45021 | D31: Yes | E31: 39 | F31: month | G31: =IF(C31="","",C31-B31) -> 213 | H31: =TEXT(B31,"dddd") -> Sunday | I31: =IF(B31=C31,"Yes","No") -> No | J31: =IF(AND(C31<>"",C31-B31<=2),1,0) -> 0 | K31: =IF(AND(C31<>"",C31-B31>30),1,0) -> 1 | L31: =IF(C31="","",C31-B31) -> 213
A32: 153194806 | B32: 44808 | C32: 45032 | D32: Yes | E32: 39 | F32: month | G32: =IF(C32="","",C32-B32) -> 224 | H32: =TEXT(B32,"dddd") -> Sunday | I32: =IF(B32=C32,"Yes","No") -> No | J32: =IF(AND(C32<>"",C32-B32<=2),1,0) -> 0 | K32: =IF(AND(C32<>"",C32-B32>30),1,0) -> 1 | L32: =IF(C32="","",C32-B32) -> 224
A33: 144402204 | B33: 44808 | C33: 44826 | D33: Yes | E33: 39 | F33: month | G33: =IF(C33="","",C33-B33) -> 18 | H33: =TEXT(B33,"dddd") -> Sunday | I33: =IF(B33=C33,"Yes","No") -> No | J33: =IF(AND(C33<>"",C33-B33<=2),1,0) -> 0 | K33: =IF(AND(C33<>"",C33-B33>30),1,0) -> 0 | L33: =IF(C33="","",C33-B33) -> 18
... A38: 153368891 | B38: 44808 | C38: 44845 | D38: Yes | E38: 39 | F38: month | G38: =IF(C38="","",C38-B38) -> 37 | H38: =TEXT(B38,"dddd") -> Sunday | I38: =IF(B38=C38,"Yes","No") -> No | J38: =IF(AND(C38<>"",C38-B38<=2),1,0) -> 0 | K38: =IF(AND(C38<>"",C38-B38>30),1,0) -> 1 | L38: =IF(C38="","",C38-B38) -> 37
A39: 154225450 | B39: 44809 | D39: Yes | E39: 39 | F39: month | G39: =IF(C39="","",C39-B39) | H39: =TEXT(B39,"dddd") -> Monday | I39: =IF(B39=C39,"Yes","No") -> No | J39: =IF(AND(C39<>"",C39-B39<=2),1,0) -> 0 | K39: =IF(AND(C39<>"",C39-B39>30),1,0) -> 0 | L39: =IF(C39="","",C39-B39)
A40: 154904040 | B40: 44809 | C40: 44810 | D40: Yes | E40: 39 | F40: month | G40: =IF(C40="","",C40-B40) -> 1 | H40: =TEXT(B40,"dddd") -> Monday | I40: =IF(B40=C40,"Yes","No") -> No | J40: =IF(AND(C40<>"",C40-B40<=2),1,0) -> 1 | K40: =IF(AND(C40<>"",C40-B40>30),1,0) -> 0 | L40: =IF(C40="","",C40-B40) -> 1
A41: 127604200 | B41: 44809 | C41: 44840 | D41: Yes | E41: 39 | F41: month | G41: =IF(C41="","",C41-B41) -> 31 | H41: =TEXT(B41,"dddd") -> Monday | I41: =IF(B41=C41,"Yes","No") -> No | J41: =IF(AND(C41<>"",C41-B41<=2),1,0) -> 0 | K41: =IF(AND(C41<>"",C41-B41>30),1,0) -> 1 | L41: =IF(C41="","",C41-B41) -> 31
A42: 154913576 | B42: 44809 | C42: 44998 | D42: Yes | E42: 39 | F42: month | G42: =IF(C42="","",C42-B42) -> 189 | H42: =TEXT(B42,"dddd") -> Monday | I42: =IF(B42=C42,"Yes","No") -> No | J42: =IF(AND(C42<>"",C42-B42<=2),1,0) -> 0 | K42: =IF(AND(C42<>"",C42-B42>30),1,0) -> 1 | L42: =IF(C42="","",C42-B42) -> 189
A43: 154910432 | B43: 44809 | C43: 44998 | D43: Yes | E43: 39 | F43: month | G43: =IF(C43="","",C43-B43) -> 189 | H43: =TEXT(B43,"dddd") -> Monday | I43: =IF(B43=C43,"Yes","No") -> No | J43: =IF(AND(C43<>"",C43-B43<=2),1,0) -> 0 | K43: =IF(AND(C43<>"",C43-B43>30),1,0) -> 1 | L43: =IF(C43="","",C43-B43) -> 189
A44: 154911229 | B44: 44809 | C44: 44997 | D44: Yes | E44: 39 | F44: month | G44: =IF(C44="","",C44-B44) -> 188 | H44: =TEXT(B44,"dddd") -> Monday | I44: =IF(B44=C44,"Yes","No") -> No | J44: =IF(AND(C44<>"",C44-B44<=2),1,0) -> 0 | K44: =IF(AND(C44<>"",C44-B44>30),1,0) -> 1 | L44: =IF(C44="","",C44-B44) -> 188
...

Sheet Data Analysis Tasks
A1: Data Analysis Tasks:
A3: 1. Calculate the total number of subscriptions and cancellations.
C5: subscriptions | D5: =COUNT('Subscription Cohort Data'!$B$2:$B$3070) -> 3069
C6: cancellations | D6: =COUNT('Subscription Cohort Data'!C2:C3070) -> 2004
A8: 2. Determine the percentage of paid vs. unpaid subscriptions.
C10: paid | D10: =COUNTIF('Subscription Cohort Data'!$D$2:$D$3070,"yes") -> 2936 | E10: =D10/D5 -> 0.95666341
C11: unpaid | D11: =COUNTIF('Subscription Cohort Data'!$D$2:$D$3070,"no") -> 133 | E11: =D11/D5 -> 0.043336592 | H11: Row Labels | I11: Count of was_subscription_paid
H12: No | I12: 0.043336592
A13: 3. Analyze the average subscription duration before cancellation. | H13: Yes | I13: 0.95666341
H14: Grand Total | I14: 1
C15: average | D15: =AVERAGE('Subscription Cohort Data'!G2:G3070) -> 58.374251
A17: 4. Identify the date with the highest number of new subscriptions.
C19: ='Subscription Cohort Data'!J2 -> 44879
A21: 5. Find the proportion of subscriptions that were canceled within one day.
B23: subscription canceled in 1 days are | E23: =COUNTIFS(Table1[same_day_cancel],"Yes") -> 108 | F23: =E23/E24 -> 0.053892216
B24: total sus. Cancled | E24: =D6 -> 2004

Sheet Visualization & Reporting
A1: Visualization & Reporting:
M3: KPI Use
A5: 1. Create a bar chart showing the number of new subscriptions per month for year 2022.
N6: Row Labels | O6: Count of created_date
B7: Row Labels | C7: Count of created_date | N7: Sunday | O7: 306
B8: Dec | C8: 230 | N8: Monday | O8: 539
B9: Nov | C9: 189 | N9: Tuesday | O9: 487
B10: Oct | C10: 196 | N10: Wednesday | O10: 472
B11: Sep | C11: 283 | N11: Thursday | O11: 505
B12: Aug | C12: 268 | N12: Friday | O12: 452
B13: Jul | C13: 306 | N13: Saturday | O13: 308
B14: Jun | C14: 275 | N14: Grand Total | O14: 3069
B15: May | C15: 285
B16: Apr | C16: 223
B17: Mar | C17: 266
B18: Feb | C18: 275
B19: Jan | C19: 273
B20: Grand Total | C20: 3069
N21: Row Labels | O21: Count of created_date
N22: 2022 | O22: 832
N23: 2023 | O23: 2237
A24: 2. Generate a pie chart displaying the percentage of paid vs. unpaid subscriptions. | N24: Grand Total | O24: 3069
B28: Row Labels | C28: Count of was_subscription_paid
B29: Unpaid | C29: 0.043336592
B30: Paid | C30: 0.95666341
B31: Grand Total | C31: 1
A40: 3. Plot a line graph of subscription cancellations over time.
B42: Row Labels | C42: Count of canceled_date
B43: 2022 | C43: 346
B44: 2023 | C44: 1658
B45: Grand Total | C45: 2004

Sheet Requirements
A32: Expected Dashboard

Sheet DashBoard
B5: =GETPIVOTDATA("created_date",'Visualization & Reporting'!$N$21) -> 3069 | F5: =GETPIVOTDATA("canceled_date",'Visualization & Reporting'!$B$42) -> 2004 | J5: =GETPIVOTDATA("was_subscription_paid",'Visualization & Reporting'!$B$28,"was_subscription_paid","Paid") -> 0.95666341 | M5: =GETPIVOTDATA("was_subscription_paid",'Visualization & Reporting'!$B$28,"was_subscription_paid","Unpaid") -> 0.043336592
